Workbook
Name GA: [1]Lists!$C$3:INDEX([1]Lists!$C$3:$C$10,COUNTIF([1]Lists!$C$3:$C$10,"?*"))
Name GeeAye: [1]Lists!$C$12:INDEX([1]Lists!$C$12:$C$18,COUNTIF([1]Lists!$C$12:$C$18,"?*"))
Name Instructions: [2]Lists!$C$3:INDEX([2]Lists!$C$3:$C$10,COUNTIF([2]Lists!$C$3:$C$10,"?*"))
Name P1Rating: '[3]QA7 (P1-P4) '!$AK$1:$AL$5
Name P2Rating: '[3]QA7 (P1-P4) '!$AM$1:$AN$5
Name P3Rating: '[3]QA7 (P1-P4) '!$AO$1:$AP$5
Name P4Rating: '[3]QA7 (P1-P4) '!$AQ$1:$AR$5
Name PLCodeTable: '[3]Staff Data'!$AF$5:$AF$14
Name PS2Criterion1: [1]Lists!$C$3:INDEX([1]Lists!$C$3:$C$10,COUNTIF([1]Lists!$C$3:$C$10,"?*"))
Name PS2Criterion1: [4]Lists!$C$3:INDEX([4]Lists!$C$3:$C$10,COUNTIF([4]Lists!$C$3:$C$10,"?*"))
Name PS2Criterion1: [5]Lists!$C$3:INDEX([5]Lists!$C$3:$C$10,COUNTIF([5]Lists!$C$3:$C$10,"?*"))
Name PS2Criterion1: [4]Lists!$C$3:INDEX([4]Lists!$C$3:$C$10,COUNTIF([4]Lists!$C$3:$C$10,"?*"))
Name PS2Criterion2: [1]Lists!$C$12:INDEX([1]Lists!$C$12:$C$18,COUNTIF([1]Lists!$C$12:$C$18,"?*"))
Name PS2Criterion2: [4]Lists!$C$12:INDEX([4]Lists!$C$12:$C$18,COUNTIF([4]Lists!$C$12:$C$18,"?*"))
Name PS2Criterion2: [5]Lists!$C$12:INDEX([5]Lists!$C$12:$C$18,COUNTIF([5]Lists!$C$12:$C$18,"?*"))
Name PS2Criterion2: [4]Lists!$C$12:INDEX([4]Lists!$C$12:$C$18,COUNTIF([4]Lists!$C$12:$C$18,"?*"))
Name PS5Criterion1: [1]Lists!$C$21:INDEX([1]Lists!$C$21:$C$26,COUNTIF([1]Lists!$C$21:$C$26,"?*"))
Name PS5Criterion1: [4]Lists!$C$21:INDEX([4]Lists!$C$21:$C$26,COUNTIF([4]Lists!$C$21:$C$26,"?*"))
Name PS5Criterion1: [5]Lists!$C$21:INDEX([5]Lists!$C$21:$C$26,COUNTIF([5]Lists!$C$21:$C$26,"?*"))
Name PS5Criterion1: [4]Lists!$C$21:INDEX([4]Lists!$C$21:$C$26,COUNTIF([4]Lists!$C$21:$C$26,"?*"))
Name PS5Criterion2: [1]Lists!$C$28:INDEX([1]Lists!$C$28:$C$33,COUNTIF([1]Lists!$C$28:$C$33,"?*"))
Name PS5Criterion2: [4]Lists!$C$28:INDEX([4]Lists!$C$28:$C$33,COUNTIF([4]Lists!$C$28:$C$33,"?*"))
Name PS5Criterion2: [5]Lists!$C$28:INDEX([5]Lists!$C$28:$C$33,COUNTIF([5]Lists!$C$28:$C$33,"?*"))
Name PS5Criterion2: [4]Lists!$C$28:INDEX([4]Lists!$C$28:$C$33,COUNTIF([4]Lists!$C$28:$C$33,"?*"))
Name PS5Criterion3: [1]Lists!$C$35:INDEX([1]Lists!$C$35:$C$39,COUNTIF([1]Lists!$C$35:$C$39,"?*"))
Name PS5Criterion3: [4]Lists!$C$35:INDEX([4]Lists!$C$35:$C$39,COUNTIF([4]Lists!$C$35:$C$39,"?*"))
Name PS5Criterion3: [5]Lists!$C$35:INDEX([5]Lists!$C$35:$C$39,COUNTIF([5]Lists!$C$35:$C$39,"?*"))
Name PS5Criterion3: [4]Lists!$C$35:INDEX([4]Lists!$C$35:$C$39,COUNTIF([4]Lists!$C$35:$C$39,"?*"))
Name PS6Criterion1: [1]Lists!$C$42:INDEX([1]Lists!$C$42:$C$47,COUNTIF([1]Lists!$C$42:$C$47,"?*"))
Name PS6Criterion1: [4]Lists!$C$42:INDEX([4]Lists!$C$42:$C$47,COUNTIF([4]Lists!$C$42:$C$47,"?*"))
Name PS6Criterion1: [5]Lists!$C$42:INDEX([5]Lists!$C$42:$C$47,COUNTIF([5]Lists!$C$42:$C$47,"?*"))
Name PS6Criterion1: [4]Lists!$C$42:INDEX([4]Lists!$C$42:$C$47,COUNTIF([4]Lists!$C$42:$C$47,"?*"))
Name PS7Criterion1: [1]Lists!$C$50:INDEX([1]Lists!$C$50:$C$55,COUNTIF([1]Lists!$C$50:$C$55,"?*"))
Name PS7Criterion1: [6]Lists!$C$50:INDEX([6]Lists!$C$50:$C$55,COUNTIF([6]Lists!$C$50:$C$55,"?*"))
Name PS7Criterion1: [7]Lists!$C$50:INDEX([7]Lists!$C$50:$C$55,COUNTIF([7]Lists!$C$50:$C$55,"?*"))
Name PS7Criterion1: [4]Lists!$C$50:INDEX([4]Lists!$C$50:$C$55,COUNTIF([4]Lists!$C$50:$C$55,"?*"))
Name rating: '[8]Appr. Instr. Principal (D2)'!#REF!
Name rating: '[7]Appraisal Instr. (D2)'!#REF!
Name rating: '[9]Appraisal Instr. (D2)'!#REF!
Name RatingTable: '[3]Staff Data'!$W$3:$X$12

Sheet Cover Sheet
A1: Appraisal Instrument (Post Level 1) Educators
A3: 1 | B3: Introduction
A4: 1.1 | B4: The performance appraisal of an educator (Post Level 1) must be conducted twice during the year, using the approved instrument provided in this section.
A5: 1.2 | B5: The two appraisals are conducted as follows: ○ Mid-year, and ○ Annual
A6: 2 | B6: The Instrument
A7: 2.1 | B7: The QMS instrument (Annexure A 1) must be completed for each educator on post level 1.
A8: 2.2 | B8: The instrument should also be used for purposes of self-appraisal, the mid-year appraisal and final appraisal.
A9: 2.3 | B9: The instrument consists of 5 Performance Standards
A10: 2.4 | B10: The Performance Standards in the instrument form the core elements of the job description for educators.
A11: 2.5 | B11: The criteria form the key deliverables for each Performance Standard.
A12: 2.6 | B12: The desired outcome/key objective of each criteria has been pegged with a maximum rating of 4.
A13: 2.7 | B13: When completing the instrument, the appraiser/supervisor must use the rating guide which provides the elements for the key descriptors for ratings that range from 1 – 4.
A14: 2.8 | B14: A rating that is less than the desired outcome will be influenced by the following factors:
B15: ○There is no or insufficient evidence of a particular desired activity
B16: ○The desired activity is infrequent
B17: ○The desired activity is frequent but of poorer quality than desired;
B18: ○The desired activity is infrequent and of poor quality; and
B19: ○The desired activity may be frequent and of reasonable quality but is impacted by a negative attitude
A21: 3 | B21: Performance Standards
A22: Table 1 below shows the Performance Standards, the criteria and the desired outcomes for PL 1 educators
A23: Table 1: Performance Standards and criteria for PL 1 educators
B24: Performance Standard | C24: Criteria | E24: The desired outcome
A25: 1 | B25: Creation of a positive learning environment | C25: Learning and teaching environment | E25: The use of learning and teaching environment enables all learners to be productively engaged in individual and cooperative learning.
C26: Classroom Management | E26: Time and available resources are managed to promote optimal learning and teaching for all learners. Activities are efficiently supervised. Learners work together with the educator towards the achievement of relevant learning outcomes.
A27: 2 | B27: Curriculum knowledge, lesson planning and presentation | C27: Knowledge of subject | E27: Uses expert knowledge, in addition to Outcomes and Assessment Standards, to promote learner interest and research in the specific Learning Area/Subject.
C28: Planning and presentation | E28: Effective use of planning instruments leads towards a higher form of learning/ understanding.
C29: Management of work schedule | E29: Excellent management of content and context within the timeframes stipulated in the Work Schedule accompanied by relevant intervention strategies.
C30: Record keeping | E30: Records are meticulously maintained and analysed to diagnose learner needs and teaching effectiveness. Records are used to adjust teaching strategies and improve learner achievement
A31: 3 | B31: Learner assessment and achievement | C31: Feedback to learners | E31: Provides feedback using a variety of strategies. Uses remedial and enrichment measures that instill confidence in learners to achieve intended learning outcomes.
C32: Knowledge and application of forms of assessment | E32: Knows and uses a range of forms of assessment techniques to continuously maximise learner achievement. Methods of assessment are used to raise the standards of teaching and learning.
C33: Learner progress and achievement | E33: Learners optimally achieve the relevant Learning Area/ Subject outcomes. Assessment results show outstanding levels of competence and achievement.
A34: 4 | B34: Professional Development | C34: Participation in Continuous professional development | E34: Participates fully and takes a leading role in initiating and delivering professional development activities.
C35: Educator professionalism | E35: Educator is exemplary and truly displays the purpose and intent of the educators’ code of professional ethics.
A36: 5 | B36: Extra-mural and co-curricular participation | C36: Participation in extra-mural and co-curricular activities | E36: Networks with relevant stakeholders and encourages development of extra-mural or co-curricular activities.
A37: 4. Rating Scale, Descriptor, scores and percentages:
A38: 4.1 Post Level 1 Educators
A39: A 4 point rating scale is used when completing the instrument.
A40: Rating | B40: Descriptor | H40: Score (Maximum Score = 152) | I40: Percentage
A41: 1 | B41: Unacceptable: The level of performance does not meet minimum expectations and requires urgent intervention and support | H41: 0-75 | I41: 0%-49%
A42: 2 | B42: Acceptable: Satisfies minimum expectations. The level of performance is acceptable and is in line with the minimum expectations, but development and support are still required | H42: 76-105 | I42: 50%-69%
...

Sheet Instructions
B2: Guide for the completion of templates for Educators (PL1)
B4: Step 1: Start with TAB "Appraisal Instrument (A1)" | D4: This information will populate the:
B6: A | C6: Fill in "Section A: EDUCATOR AND SCHOOL INFORMATION"
B7: 1. | C7: APPRAISEE | D7: · Composite Score Sheet (A2)
B8: 2. | C8: APPRAISER | D8: · Lesson Observation Instrument (LOI) (E2)
B9: 3. | C9: SCHOOL | D9: · Checklist
B10: 4. | C10: EDUCATOR’S BRIEF JOB DESCRIPTION (Subjects/Grades/Key areas of responsibility, etc)
B12: Step 2: Self-appraisal by the educator | D12: The educator must conduct a self-appraisal prior to the appraisal by his/her supervisor. A printed copy must be kept on record.
B14: Step 3: Complete the "Lesson Observation Instrument (E2)" | D14: These scores will populate Performance Standards 1, 2 & 3 on the Appraisal Instrument (A1).
B16: Step 4: Complete Performance Standards 4 and 5 on the "Appraisal Instrument (A1)" | D16: These scores will populate the 'Composite Score Sheet (A2)'.
B18: Step 5: Complete the "Composite Score Sheet (A2)" | D18: Select two development needs and select whether you agree or disagree with the overall performance rating.
B20: Step 6: Complete the "Checklist" to ensure full compliance
B22: Step 7: Naming your file: please save your file as follows: SURNAME_INITIAL_PERSAL_PL1_2026 (e.g. DU TOIT_AB_5135635_PL1_2026)

Sheet Appraisal Instrument (A1) 
E1: Annexure A1
A2: QUALITY MANAGEMENT SYSTEM (QMS)
A3: SELF-APPRAISAL INSTRUMENT
A4: EDUCATOR: POST LEVEL 1
A6: Section A: EDUCATOR AND SCHOOL INFORMATION
A8: 1. APPRAISEE
A9: Surname | C9: AFRICA | D9: First names | E9: CHARMAINE PAIGE
A10: Designation | C10: Teacher (PL1) | D10: Persal number | E10: 50467948
A11: Highest Qualification | C11: BA DEGREE & JP DIPLOMA | D11: Specialization in subject domain | E11: GRADE 1 & GRADE 2
A12: Grade / Subjects taught during current appraisal year | D12: HOME LANGUAGE FIRST ADDITIONAL LANGUAGE AND MATHEMATICS
A14: 2. APPRAISER
A15: Surname | C15: SNYMAN | D15: First names | E15: MELENIE
A16: Designation | C16: Acting Departmental Head (PL2) | D16: Persal number | E16: 50591070
A18: 3. SCHOOL
A19: Name of school | C19: MATROOSFONTEIN PRIMARY | D19: Province | E19: Western Cape
A20: District | C20: Metro North | D20: Principal’s name | E20: MS D. MARTIN
A21: School telephone | C21: 210232155 | D21: Cell No | E21: 606029832
A23: 4. EDUCATOR’S BRIEF JOB DESCRIPTION (Subjects/Grades/Key areas of responsibility, etc)
A24: Teaching and assessment responsibilities | C24: Extra-mural activities | D24: Administrative duties | E24: Other: (Please specify)
A25: TEACHING AND ASSESSMENT RESPONSIBILITIES. IN GRADE 1 AND 2 (MULTIGRADE CLASS) | C25: SPORT | D25: KEEPING RECORD OF CLASS REGISTER. MARKING OF WORKSHEETS AND TASKS. RECORDING OF OBSERVATION SHEETS AND PROGRESS REPORTS | E25: -
A27: SECTION B: APPRAISAL
A28: Educator to be rated by selecting or entering a value between 1-4 for each descriptor
A29: PERFORMANCE STANDARD 1: CREATION OF A POSITIVE LEARNING AND TEACHER ENVIRONMENT
A31: Criterion 1: Learning and teaching environment | D31: Mid-Year | E31: Annual
A32: a. | B32: Seating arrangement promotes effective teaching and learning | D32: ='Less Ob Instr (E2)'!D17 -> 3 | E32: ='Less Ob Instr (E2)'!F17 -> 0
A33: b. | B33: Classroom is tidy and clean | D33: ='Less Ob Instr (E2)'!D18 -> 3 | E33: ='Less Ob Instr (E2)'!F18 -> 0
A34: c. | B34: Teaching and learning support material (e.g. charts) are displayed and used in the classroom. | D34: ='Less Ob Instr (E2)'!D19 -> 3 | E34: ='Less Ob Instr (E2)'!F19 -> 0
A35: Sub-total | D35: =SUM(D32:D34) -> 9 | E35: =SUM(E32:E34) -> 0
A37: Criterion 2: Classroom Management | D37: Mid-Year | E37: Annual
A38: a. | B38: Is punctual and organized in class | D38: ='Less Ob Instr (E2)'!D21 -> 3 | E38: ='Less Ob Instr (E2)'!F21 -> 0
A39: b. | B39: Ensures that learners are punctual and settle down quickly | D39: ='Less Ob Instr (E2)'!D22 -> 3 | E39: ='Less Ob Instr (E2)'!F22 -> 0
A40: c. | B40: Communication between educator and learners reflects mutual respect, cooperation and understanding | D40: ='Less Ob Instr (E2)'!D23 -> 3 | E40: ='Less Ob Instr (E2)'!F23 -> 0
A41: d. | B41: Manages discipline effectively | D41: ='Less Ob Instr (E2)'!D24 -> 3 | E41: ='Less Ob Instr (E2)'!F24 -> 0
A42: Sub-total | D42: =SUM(D38:D41) -> 12 | E42: =SUM(E38:E41) -> 0
A43: Total for Performance Standard 1 | D43: =D35+D42 -> 21 | E43: =E35+E42 -> 0
A44: Comments (compulsory)
A45: Mid-Year
A46: Annual
A48: PERFORMANCE STANDARD 2: CURRICULUM KNOWLEDGE, LESSON PLANNING AND PRESENTATION
A50: Criterion 1: Knowledge of subject | D50: Mid-Year | E50: Annual
...

Sheet Less Ob Instr (E2)
B2: Annexure E 2
B3: Lesson Observation Instrument (LOI) | F3: Post Level 1: Teacher
B5: Appraisee Surname & Name: | E5: ='Appraisal Instrument (A1) '!C9 -> AFRICA | F5: ='Appraisal Instrument (A1) '!E9 -> CHARMAINE PAIGE
B6: PERSAL | E6: ='Appraisal Instrument (A1) '!E10 -> 50467948
B7: Appraiser Surname and Name | E7: ='Appraisal Instrument (A1) '!C15 -> SNYMAN | F7: ='Appraisal Instrument (A1) '!E15 -> MELENIE
B8: PERSAL | E8: ='Appraisal Instrument (A1) '!E16 -> 50591070
E10: Mid-Year | F10: Annual
B11: Grade: | E11: GRADE 1 AND GRADE 2 (MULITIGRADE)
B12: Subject / Learning Area: | E12: MATHEMATICS
B13: Lesson Topic: | E13: DATAHANDLING
B15: PERFORMANCE STANDARD 1 | E15: CREATION OF A POSITIVE LEARNING AND TEACHING ENVIRONMENT
B16: Criterion 1: Learning and teaching environment | D16: Mid-Year Rating | E16: Mid-Year Remarks (compulsory) | F16: Annual Rating | G16: Annual Remarks (compulsory)
B17: a | C17: Seating arrangement promotes effective teaching and learning | D17: 3 | E17: Most of the learners faced the writing board and it helps a lot with the reverse numbers and letters.
B18: b | C18: Classroom is tidy and clean | D18: 3
B19: c | C19: Teaching and learning support material (e.g. charts) are displayed and used in the classroom. | D19: 3
B20: Criterion 2: Classroom Management | D20: Mid-Year Rating | E20: Mid-Year Remarks (compulsory) | F20: Annual Rating | G20: Annual Remarks (compulsory)
B21: a | C21: Is punctual and organized in class | D21: 3 | E21: Some children is coming late due to transport. They communicate well and adapt easy in class.
B22: b | C22: Ensures that learners are punctual and settle down quickly | D22: 3
B23: c | C23: Communication between educator and learners reflects mutual respect, cooperation and understanding | D23: 3
B24: d | C24: Manages discipline effectively | D24: 3
D25: =SUM(D17:D19,D21:D24) -> 21 | E25: Mid-Year Subtotal | F25: =SUM(F17:F19,F21:F24) -> 0 | G25: Annual Subtotal
B27: PERFORMANCE STANDARD 2 | E27: CURRICULUM KNOWLEDGE, LESSON PLANNING AND PRESENTATION
B28: Criterion 1: Knowledge of subject | D28: Mid-Year Rating | E28: Mid-Year Remarks (compulsory) | F28: Annual Rating | G28: Annual Remarks (compulsory)
B29: a | C29: Has adequate subject knowledge and uses it effectively | D29: 3 | E29: Doing a grade 1 and 2 class (multigrade) and is going well.
B30: b | C30: Sets appropriate tasks for learners at the level of the Grade | D30: 3
B31: c | C31: Uses a variety of examples, LTSM and other teaching resources to facilitate learning | D31: 2
B32: Criterion 2: Planning and presentation | D32: Mid-Year Rating | E32: Mid-Year Remarks (compulsory) | F32: Annual Rating | G32: Annual Remarks (compulsory)
B33: a | C33: Lesson is logical, coherent and meaningful to learners | D33: 3 | E33: Lesson planning is logical. The basic concepts stay the same. Grade 2 is only working on a higher number range etc.
B34: b | C34: Lesson is built on past knowledge and experience of learners | D34: 3
B35: c | C35: Time is well-managed during lesson presentation | D35: 3
B36: d | C36: Encourages interactive learning including class discussions, learner questions and demonstrations | D36: 3
B37: e | C37: Responds appropriately to learner questions and inputs | D37: 2
B38: Criterion 3: Management of work schedule | D38: Mid-Year Rating | E38: Mid-Year Remarks (compulsory) | F38: Annual Rating | G38: Annual Remarks (compulsory)
B39: a | C39: Pace of the work is in line with time frames stipulated in the work schedule | D39: 3 | E39: Pace of the writing work is abit slow due to multigrade class. (Grade 1 and 2). Groupwork needs a lot of attention.
B40: b | C40: Number of tasks and activities are in line with NCS/CAPS | D40: 2
B41: Criterion 4: Recordkeeping | D41: Mid-Year Rating | E41: Mid-Year Remarks (compulsory) | F41: Annual Rating | G41: Annual Remarks (compulsory)
B42: a | C42: File/files neatly kept, organized and updated regularly | D42: 3 | E42: Recording and keep track of individual is kept on classlists. Work with data.
B43: b | C43: Records of learner assessments are neatly kept, organized and updated regularly | D43: 3
D44: =SUM(D29:D31,D33:D37,D39:D40,D42:D43) -> 33 | E44: Mid-Year Subtotal | F44: =SUM(F29:F31,F33:F37,F39:F40,F42:F43) -> 0 | G44: Annual Subtotal
B46: PERFORMANCE STANDARD 3 | E46: LEARNER ASSESSMENT AND ACHIEVEMENT
...

Sheet Composite Score Sheet (A2)
A2: QUALITY MANAGEMENT SYSTEM (QMS) COMPOSITE SCORE SHEET: PL 1 Educator | E2: Annexure A2
A3: (To be submitted to the District Office by the end of the 4th Quarter)
A4: Mid-Year Date | C4: 15 MAY 2026 | D4: #VALUE!
A5: Annual Date
A6: Surname | C6: ='Appraisal Instrument (A1) '!C9 -> AFRICA
A7: First Name | C7: ='Appraisal Instrument (A1) '!E9 -> CHARMAINE PAIGE
A8: Persal Number | C8: ='Appraisal Instrument (A1) '!E10 -> 50467948
A9: School Name | C9: ='Appraisal Instrument (A1) '!C19 -> MATROOSFONTEIN PRIMARY
A11: NO. | B11: PERFORMANCE STANDARD | D11: MAXIMUM SCORE | E11: MID-YEAR | F11: ANNUAL
A12: 1 | B12: Creation of positive learning and teaching environment | D12: 28 | E12: ='Appraisal Instrument (A1) '!D43 -> 21 | F12: ='Appraisal Instrument (A1) '!E43 -> 0
A13: 2 | B13: Curriculum knowledge, lesson planning and presentation | D13: 48 | E13: ='Appraisal Instrument (A1) '!D73 -> 33 | F13: ='Appraisal Instrument (A1) '!E73 -> 0
A14: 3 | B14: Learner assessment and achievement | D14: 28 | E14: ='Appraisal Instrument (A1) '!D95 -> 20 | F14: ='Appraisal Instrument (A1) '!E95 -> 0
A15: 4 | B15: Professional development | D15: 36 | E15: ='Appraisal Instrument (A1) '!D117 -> 22 | F15: ='Appraisal Instrument (A1) '!E117 -> 0
A16: 5 | B16: Extra-mural and co-curricular participation | D16: 12 | E16: ='Appraisal Instrument (A1) '!D128 -> 8 | F16: ='Appraisal Instrument (A1) '!E128 -> 0
A17: FINAL SCORE | D17: =SUM(D12:D16) -> 152 | E17: =SUM(E12:E16) -> 104 | F17: =SUM(F12:F16) -> 0
A18: PERCENTAGE (Educator Score ÷ 152) x 100 = | E18: =E17/D17 -> 0.68421053 | F18: =F17/D17 -> 0
A20: Comments : Strengths and areas for development (compulsory)
A21: How to manage multigrade classes better.
A23: Identified development needs (compulsory)
A24: Choice 1 | D24: Choice 2
A25: Blended learning training | D25: Coding and robotics
A27: I agree with the overall performance rating
A28: MID-YEAR APPRAISAL SIGNATURES:
A29: Name of Appraisee | C29: ='Appraisal Instrument (A1) '!C9 -> AFRICA | E29: ='Appraisal Instrument (A1) '!E9 -> CHARMAINE PAIGE
A30: Signature & Date: | E30: 15 MAY 2026
A31: Name of Appraiser | C31: ='Appraisal Instrument (A1) '!C15 -> SNYMAN | E31: ='Appraisal Instrument (A1) '!E15 -> MELENIE
A32: Signature & Date:
A33: Name of Resource Person (Optional):
A34: Signature & Date: (Optional)
A36: ANNUAL APPRAISAL SIGNATURES:
A37: Name of Appraisee | C37: ='Composite Score Sheet (A2)'!C6 -> AFRICA | E37: =E29 -> CHARMAINE PAIGE
A38: Signature & Date:
A39: Name of Appraiser | C39: =C31 -> SNYMAN | E39: =E31 -> MELENIE
A40: Signature & Date:
A41: Name of Resource Person (Optional):
A42: Signature & Date: (Optional)
A44: VALIDATED BY :
A45: Principal | C45: ='Appraisal Instrument (A1) '!E20 -> MS D. MARTIN
A46: Signature:
A47: Date:
...

Sheet Checklist
B2: Western Cape Education Department | E2: #VALUE!
B6: Quality Management System (QMS) Checklist for Teachers (PL1)
B8: Please ensure that this checklist is completed to ensure full compliance:
E10: Mid-Year | F10: Annual
B11: 1 | C11: General Requirements | E11: Select YES/NO | F11: Select YES/NO
B12: 1.1 | C12: I have a signed WCED Job Description (JD) on file. | E12: YES | F12: NO
B13: 1.2 | C13: I have read and understood the Appraisal Instrument, including the Performance Standards (PS) and the expected outcomes. | E13: YES | F13: NO
B14: 1.3 | C14: I have selected my two developmental needs (in collaboration with my supervisor) which will be incorporated into the Staff Development Plan (SDP) and captured on the school's Annexure E1. | E14: YES | F14: NO
B15: 1.4 | C15: I have read and understood the 'Instructions' sheet for completing the relevant templates. | E15: YES | F15: NO
B17: 2 | C17: Annexure A1: Performance Standards | E17: Select YES/NO | F17: Select YES/NO
B18: 2.1 | C18: All comments are comprehensive, informative, and relevant to the current appraisal cycle. | E18: YES | F18: NO
B19: 2.2 | C19: Each Performance Standard includes a completed score. | E19: YES | F19: NO
B20: 2.3 | C20: The Appraisee, Appraiser, and Principal have signed Annexure A1. | E20: YES | F20: NO
B21: 2.4 | C21: I have completed my Self-Appraisal Instrument and signed it. | E21: YES | F21: NO
B22: 2.5 | C22: The school stamp is attached. | E22: YES | F22: NO
B24: 3 | C24: Annexure E2: Lesson Observation | E24: Select YES/NO | F24: Select YES/NO
... B32: 4.4 | C32: I have selected my two developmental needs (in collaboration with my supervisor) which will be incorporated into the Staff Development Plan (SDP) and captured on the school's Annexure E1. | E32: YES | F32: NO
B34: Mid-Year Appraisal Signatures
B35: Name of Appraisee | D35: ='Appraisal Instrument (A1) '!C9 -> AFRICA | F35: ='Appraisal Instrument (A1) '!E9 -> CHARMAINE PAIGE
B36: Signature & Date:
B37: Name of Appraiser | D37: ='Appraisal Instrument (A1) '!C15 -> SNYMAN | F37: ='Appraisal Instrument (A1) '!E15 -> MELENIE
B38: Signature & Date:
B40: Annual Appraisal Signatures
B41: Name of Appraisee | D41: ='Appraisal Instrument (A1) '!C9 -> AFRICA | F41: ='Appraisal Instrument (A1) '!E9 -> CHARMAINE PAIGE
B42: Signature & Date:
B43: Name of Appraiser | D43: ='Appraisal Instrument (A1) '!C15 -> SNYMAN | F43: ='Appraisal Instrument (A1) '!E15 -> MELENIE
B44: Signature & Date:
B45: School Stamp

Sheet LISTS
B2: YEAR | C2: Designation | D2: Districts | E2: SELF-APPRAISAL INSTRUMENT
B3: 2025 | C3: Teacher (PL1) | D3: Metro Central | E3: APPRAISAL INSTRUMENT
B4: 2026 | C4: Senior Teacher (PL1) | D4: Metro East
B5: 2027 | C5: Master Teacher (PL1) | D5: Metro North | E5: Select a statement
B6: 2028 | C6: Departmental Head (PL2) | D6: Metro South | E6: I agree with the overall performance rating
B7: 2029 | C7: Acting Departmental Head (PL2) | D7: Cape Winelands | E7: I do not agree with the overall performance rating
B8: 2030 | C8: Deputy Principal (PL3) | D8: Eden & Central Karoo
C9: Acting Deputy Principal (PL3) | D9: Overberg | E9: YES
C10: Principal (PL4) | D10: West Coast | E10: NO
C11: Acting Principal (PL4)
C12: Circuit Manager (PL6)
C13: Acting Circuit Manager (PL6)

Sheet TN
A1: SCHOOL NAME | C1: PL4 | D1: PL3 | E1: PL2 | F1: PL1
A2: A.C.J. PHAKADE PRIMARY SCHOOL | C2: Asset management | D2: Analysis of results | E2: Administration and resources management | F2: Analysis of results Training
A3: A.F. KRIEL VGK PRIMÊRE SKOOL | C3: Budget control | D3: Assessment management | E3: Administration of resources and records | F3: Artificial intelligence (A.I) for educators
A4: A.F. LOUW LAERSKOOL | C4: Change management | D4: Asset and records management | E4: Analysis of results | F4: Assessment techniques
A5: A.H. BARNARD PRIMÊRE SKOOL | C5: Classroom visits | D5: Budget control | E5: Artificial Intelligence (A.I) for educators | F5: Autism spectrum disorder training
A6: A.Z. BERMAN HIGH SCHOOL | C6: Coaching & mentorship skills | D6: Change management | E6: Assessment | F6: Blended learning training
A7: A.Z. BERMAN PRIMARY SCHOOL | C7: Conflict management | D7: Coaching & mentorship skills | E7: Blended learning training | F7: Coding and robotics
A8: AAN DE DOORNS NGK PRIMÊRE SKOOL | C8: Curriculum management | D8: Computer Literacy | E8: Budget control | F8: Communication and presentation skills
A9: ABBOTT'S COLLEGE RONDEBOSCH | C9: Decision-making skills | D9: Conflict management | E9: Change management | F9: Computer Literacy
A10: ABC EDUCARE CENTRE | C10: Delegation of tasks and responsibilities | D10: Curriculum management | E10: Coding and robotics | F10: Conflict management
A11: ABEDARE PRIMARY SCHOOL | C11: Delegation skills | D11: Data management and data analysis | E11: Communication and Presentation Skills | F11: Curriculum development to enhance teaching and learning
A12: ABEILLE RUCHE SCHOOL | C12: Design thinking training programme | D12: Decision making and accountability | E12: Conflict management | F12: Curriculum Knowledge, Lesson Planning & Presentation
... A58: ANNE PIENAAR GEDENK NGK PRIMÊRE SKOOL | C58: Time to think | D58: Upskilling in excel | E58: Records management aligned to curriculum | F58: Records management aligned to curriculum
A59: ANNE'S TODDLERS PREPRIMARY SCHOOL | C59: WCED systems training (e.g. CEMIS, PERMIS) | E59: Relationship building and networking | F59: Relationship building and networking
A60: APEX HIGH SCHOOL | C60: Year planner: keeping a record of important events at school | E60: Roles & responsibilities of Departmental Heads | F60: Remedial intervention strategies
A61: APEX NETWORK OF SCHOOLS NPC TRADING AS APEX STELLE | E61: Self-reflection for improved performance | F61: Smart board classroom
A62: APEX PRIMARY SCHOOL | E62: Thinking skills | F62: Specialised sports coaching
A63: APPLEWOOD PREPARATORY SCHOOL | E63: Time management | F63: Standard setting for question papers
A64: AQUILA HIGH SCHOOL | E64: Timetable creation | F64: STEM teaching
A65: ARCADIA PRIMARY SCHOOL | E65: Training for Departmental Heads | F65: Strategies and techniques for building a positive classroom environment
A66: ARCADIA SENIOR SEKONDÊRE SKOOL | E66: Training on admissions and enrolment | F66: Teaching learners who are on the spectrum
A67: ARIESKRAAL SSKV PRIMÊRE SKOOL | E67: Trauma sensitive classroom | F67: Teaching learners with barriers to learning
A68: ARISTEA PRIMARY SCHOOL | F68: Teaching reading skills to older learners
A69: ASHBURY PRIMÊRE SKOOL | F69: Thinking skills Training
A70: ASHFORD CHRISTIAN SCHOOL | F70: Time management Training
A71: ASHRON PRE-PRIMARY SCHOOL | F71: Timetabling training
A72: ASHTON LAERSKOOL | F72: Trauma sensitive classroom
A73: ASHTON PUBLIC COMBINED SCHOOL | F73: Understanding differentiated learning styles
A74: ASHTON SEKONDÊRE SKOOL | F74: Understanding research-based teaching techniques
A75: ASHTON VOCATIONAL ACADEMY | F75: White board training
A76: ASTRA SKOOL
A77: ATHLONE NORTH PRIMARY SCHOOL
A78: ATHLONE PREPRIMARY SCHOOL
A79: ATHLONE SECONDARY SCHOOL
A80: ATHLONE SKOOL VIR BLINDES
A81: ATHWOOD PRIMARY SCHOOL
A82: ATLANTIC BEACH COLLEGE
A83: ATLANTIS METHODIST EDUCARE CENTRE
A84: ATLANTIS SEKONDÊRE SKOOL
A85: ATLANTIS VAARDIGHEIDSKOOL
...
